Workbook
Name MinSolverVola: 'Option Param Details'!$B$12
Name MaxSolverVola: 'Option Param Details'!$B$11
Name DividendYield: 'Option Param Details'!$B$4
Name Underlying: 'Option Param Details'!$B$2
Name TimeToExpiration: 'Option Param Details'!$B$9
Name RiskFreeRate: 'Option Param Details'!$B$3

Sheet Output Stats
A3: Absolute Price Err
A4: Overall | E4: Calls Only | I4: Puts Only
A5: Min | B5: Median | C5: Mean | D5: Max | E5: Min | F5: Median | G5: Mean | H5: Max | I5: Min | J5: Median | K5: Mean | L5: Max
A6: =MIN(E6,I6) -> 4.6463793e-06 | B6: =MEDIAN('Call Vola Solver'!D$5:D$39, 'Put Vola Solver'!D$5:D$39) -> 0.00010211154 | C6: =AVERAGE('Call Vola Solver'!D$5:D$39, 'Put Vola Solver'!D$5:D$39) -> 0.016875977 | D6: =MAX(H6,L6) -> 0.7752025 | E6: =MIN('Call Vola Solver'!D$5:D$39) -> 4.6463793e-06 | F6: =MEDIAN('Call Vola Solver'!D$5:D$39) -> 0.00011495926 | G6: =AVERAGE('Call Vola Solver'!D$5:D$39) -> 0.011494481 | H6: =MAX('Call Vola Solver'!D$5:D$39) -> 0.20939776 | I6: =MIN('Put Vola Solver'!D$5:D$39) -> 6.9807078e-06 | J6: =MEDIAN('Put Vola Solver'!D$5:D$39) -> 8.7169937e-05 | K6: =AVERAGE('Put Vola Solver'!D$5:D$39) -> 0.022257473 | L6: =MAX('Put Vola Solver'!D$5:D$39) -> 0.7752025
A9: Relative Price Err
A10: Overall | E10: Calls Only | I10: Puts Only
A11: Min | B11: Median | C11: Mean | D11: Max | E11: Min | F11: Median | G11: Mean | H11: Max | I11: Min | J11: Median | K11: Mean | L11: Max
A12: =MIN(E12,I12) -> 1.7463709e-07 | B12: =MEDIAN('Call Vola Solver'!E$5:E$39, 'Put Vola Solver'!E$5:E$39) -> 3.3615808e-05 | C12: =AVERAGE('Call Vola Solver'!E$5:E$39, 'Put Vola Solver'!E$5:E$39) -> 0.00054006758 | D12: =MAX(H12,L12) -> 0.024112052 | E12: =MIN('Call Vola Solver'!E$5:E$39) -> 1.7463709e-07 | F12: =MEDIAN('Call Vola Solver'!E$5:E$39) -> 3.2922223e-05 | G12: =AVERAGE('Call Vola Solver'!E$5:E$39) -> 0.00033187833 | H12: =MAX('Call Vola Solver'!E$5:E$39) -> 0.005125754 | I12: =MIN('Put Vola Solver'!E$5:E$39) -> 3.1335808e-07 | J12: =MEDIAN('Put Vola Solver'!E$5:E$39) -> 3.4309393e-05 | K12: =AVERAGE('Put Vola Solver'!E$5:E$39) -> 0.00074825684 | L12: =MAX('Put Vola Solver'!E$5:E$39) -> 0.024112052
A15: Price Err Divided By Spread
A16: Overall | E16: Calls Only | I16: Puts Only
A17: Min | B17: Median | C17: Mean | D17: Max | E17: Min | F17: Median | G17: Mean | H17: Max | I17: Min | J17: Median | K17: Mean | L17: Max
A18: =MIN(E18,I18) -> 1.6694751e-06 | B18: =MEDIAN('Call Vola Solver'!F5:F39, 'Put Vola Solver'!F5:F39) -> 0.001490707 | C18: =AVERAGE('Call Vola Solver'!F5:F39, 'Put Vola Solver'!F5:F39) -> 0.0082391245 | D18: =MAX(H18,L18) -> 0.25006606 | E18: =MIN('Call Vola Solver'!F5:F39) -> 1.6694751e-06 | F18: =MEDIAN('Call Vola Solver'!F5:F39) -> 0.001364776 | G18: =AVERAGE('Call Vola Solver'!F5:F39) -> 0.0062547969 | H18: =MAX('Call Vola Solver'!F5:F39) -> 0.077043326 | I18: =MIN('Put Vola Solver'!F5:F39) -> 1.4279825e-05 | J18: =MEDIAN('Put Vola Solver'!F5:F39) -> 0.0016166381 | K18: =AVERAGE('Put Vola Solver'!F5:F39) -> 0.010223452 | L18: =MAX('Put Vola Solver'!F5:F39) -> 0.25006606
A24: GRADING SCHEME
A26: Option market data
A27: - mid prices | B27: 1
A28: - spreads | B28: 1
A29: Option param details
A30: - days to expiration | B30: 1
A31: - years to expiration | B31: 1
A32: - min/max volatility | B32: 2
A33: Call Vola solver
A34: - Fix bug | B34: 1
A35: - iteration 0 formulae | B35: 3
A36: - iteration 1 to N formulae | B36: 3
A37: - final values | B37: 3
A38: Put Vola solver
A39: - Fix bug 1 | B39: 1
A40: - Fix bug 2 | B40: 1
A41: - copying correct put data | B41: 1
A42: - iteration 0 formulae | B42: 1
A43: - iteration 1 to N formulae | B43: 1
A44: - final values | B44: 1
A45: Output stats
A46: - absolute error | B46: 1
A47: - relative error | B47: 1
A48: - error/spread | B48: 1
A50: Total | B50: =sum(B26:B49) -> 25

Sheet Option Mkt Data
A3: Strike | B3: Call Bid | C3: Call Ask | D3: Call Intrinsic Value (lower bound) | E3: Call upper bound | F3: Put Bid | G3: Put Ask | H3: Put Intrinsic Value (lower bound) | I3: Put upper bound | J3: Call Mid | K3: Put Mid | L3: Call Price Spread | M3: Put Price Spread
A5: 295 | B5: 44.699997 | C5: 45.449997 | D5: =MAX(Underlying*EXP(-DividendYield*TimeToExpiration)-A5*EXP(-RiskFreeRate*TimeToExpiration), 0) -> 44.507221 | E5: =Underlying*EXP(-DividendYield*TimeToExpiration) -> 339.25 | F5: 0.24000001 | G5: 0.25999999 | H5: =MAX(A5*EXP(-RiskFreeRate*TimeToExpiration)-Underlying*EXP(-DividendYield*TimeToExpiration), 0) -> 0 | I5: =A5*EXP(-RiskFreeRate*TimeToExpiration) -> 294.74278 | J5: =AVERAGE(B5:C5) -> 45.074997 | K5: =AVERAGE(F5:G5) -> 0.25 | L5: =C5-B5 -> 0.75 | M5: =G5-F5 -> 0.01999998
A6: 297.5 | B6: 40.199997 | C6: 43.400009 | D6: =MAX(Underlying*EXP(-DividendYield*TimeToExpiration)-A6*EXP(-RiskFreeRate*TimeToExpiration), 0) -> 42.009401 | E6: =Underlying*EXP(-DividendYield*TimeToExpiration) -> 339.25 | F6: 0.27000004 | G6: 0.29000002 | H6: =MAX(A6*EXP(-RiskFreeRate*TimeToExpiration)-Underlying*EXP(-DividendYield*TimeToExpiration), 0) -> 0 | I6: =A6*EXP(-RiskFreeRate*TimeToExpiration) -> 297.2406 | J6: =AVERAGE(B6:C6) -> 41.800003 | K6: =AVERAGE(F6:G6) -> 0.28000003 | L6: =C6-B6 -> 3.2000122 | M6: =G6-F6 -> 0.01999998
A7: 300 | B7: 39.799988 | C7: 40.199997 | D7: =MAX(Underlying*EXP(-DividendYield*TimeToExpiration)-A7*EXP(-RiskFreeRate*TimeToExpiration), 0) -> 39.511581 | E7: =Underlying*EXP(-DividendYield*TimeToExpiration) -> 339.25 | F7: 0.31 | G7: 0.31999999 | H7: =MAX(A7*EXP(-RiskFreeRate*TimeToExpiration)-Underlying*EXP(-DividendYield*TimeToExpiration), 0) -> 0 | I7: =A7*EXP(-RiskFreeRate*TimeToExpiration) -> 299.73842 | J7: =AVERAGE(B7:C7) -> 39.999992 | K7: =AVERAGE(F7:G7) -> 0.315 | L7: =C7-B7 -> 0.40000916 | M7: =G7-F7 -> 0.009999991
A8: 302.5 | B8: 35.600006 | C8: 38.050003 | D8: =MAX(Underlying*EXP(-DividendYield*TimeToExpiration)-A8*EXP(-RiskFreeRate*TimeToExpiration), 0) -> 37.01376 | E8: =Underlying*EXP(-DividendYield*TimeToExpiration) -> 339.25 | F8: 0.36000001 | G8: 0.37000001 | H8: =MAX(A8*EXP(-RiskFreeRate*TimeToExpiration)-Underlying*EXP(-DividendYield*TimeToExpiration), 0) -> 0 | I8: =A8*EXP(-RiskFreeRate*TimeToExpiration) -> 302.23624 | J8: =AVERAGE(B8:C8) -> 36.825005 | K8: =AVERAGE(F8:G8) -> 0.36500001 | L8: =C8-B8 -> 2.449997 | M8: =G8-F8 -> 0.009999991
A9: 305 | B9: 34.900009 | C9: 35.25 | D9: =MAX(Underlying*EXP(-DividendYield*TimeToExpiration)-A9*EXP(-RiskFreeRate*TimeToExpiration), 0) -> 34.51594 | E9: =Underlying*EXP(-DividendYield*TimeToExpiration) -> 339.25 | F9: 0.42000002 | G9: 0.43000001 | H9: =MAX(A9*EXP(-RiskFreeRate*TimeToExpiration)-Underlying*EXP(-DividendYield*TimeToExpiration), 0) -> 0 | I9: =A9*EXP(-RiskFreeRate*TimeToExpiration) -> 304.73406 | J9: =AVERAGE(B9:C9) -> 35.075005 | K9: =AVERAGE(F9:G9) -> 0.42500001 | L9: =C9-B9 -> 0.34999084 | M9: =G9-F9 -> 0.00999999
A10: 307.5 | B10: 30.349991 | C10: 33.699997 | D10: =MAX(Underlying*EXP(-DividendYield*TimeToExpiration)-A10*EXP(-RiskFreeRate*TimeToExpiration), 0) -> 32.01812 | E10: =Underlying*EXP(-DividendYield*TimeToExpiration) -> 339.25 | F10: 0.49000001 | G10: 0.5 | H10: =MAX(A10*EXP(-RiskFreeRate*TimeToExpiration)-Underlying*EXP(-DividendYield*TimeToExpiration), 0) -> 0 | I10: =A10*EXP(-RiskFreeRate*TimeToExpiration) -> 307.23188 | J10: =AVERAGE(B10:C10) -> 32.024994 | K10: =AVERAGE(F10:G10) -> 0.49500001 | L10: =C10-B10 -> 3.3500061 | M10: =G10-F10 -> 0.00999999
A11: 310 | B11: 30.100006 | C11: 30.25 | D11: =MAX(Underlying*EXP(-DividendYield*TimeToExpiration)-A11*EXP(-RiskFreeRate*TimeToExpiration), 0) -> 29.5203 | E11: =Underlying*EXP(-DividendYield*TimeToExpiration) -> 339.25 | F11: 0.57999998 | G11: 0.58999997 | H11: =MAX(A11*EXP(-RiskFreeRate*TimeToExpiration)-Underlying*EXP(-DividendYield*TimeToExpiration), 0) -> 0 | I11: =A11*EXP(-RiskFreeRate*TimeToExpiration) -> 309.7297 | J11: =AVERAGE(B11:C11) -> 30.175003 | K11: =AVERAGE(F11:G11) -> 0.58499998 | L11: =C11-B11 -> 0.1499939 | M11: =G11-F11 -> 0.009999991
A12: 312.5 | B12: 27.099991 | C12: 28.099991 | D12: =MAX(Underlying*EXP(-DividendYield*TimeToExpiration)-A12*EXP(-RiskFreeRate*TimeToExpiration), 0) -> 27.02248 | E12: =Underlying*EXP(-DividendYield*TimeToExpiration) -> 339.25 | F12: 0.69999999 | G12: 0.70999998 | H12: =MAX(A12*EXP(-RiskFreeRate*TimeToExpiration)-Underlying*EXP(-DividendYield*TimeToExpiration), 0) -> 0 | I12: =A12*EXP(-RiskFreeRate*TimeToExpiration) -> 312.22752 | J12: =AVERAGE(B12:C12) -> 27.599991 | K12: =AVERAGE(F12:G12) -> 0.70499998 | L12: =C12-B12 -> 1 | M12: =G12-F12 -> 0.009999991
A13: 315 | B13: 25.350006 | C13: 25.5 | D13: =MAX(Underlying*EXP(-DividendYield*TimeToExpiration)-A13*EXP(-RiskFreeRate*TimeToExpiration), 0) -> 24.52466 | E13: =Underlying*EXP(-DividendYield*TimeToExpiration) -> 339.25 | F13: 0.86000001 | G13: 0.87 | H13: =MAX(A13*EXP(-RiskFreeRate*TimeToExpiration)-Underlying*EXP(-DividendYield*TimeToExpiration), 0) -> 0 | I13: =A13*EXP(-RiskFreeRate*TimeToExpiration) -> 314.72534 | J13: =AVERAGE(B13:C13) -> 25.425003 | K13: =AVERAGE(F13:G13) -> 0.86500001 | L13: =C13-B13 -> 0.1499939 | M13: =G13-F13 -> 0.009999991
A14: 317.5 | B14: 22.699997 | C14: 23.350006 | D14: =MAX(Underlying*EXP(-DividendYield*TimeToExpiration)-A14*EXP(-RiskFreeRate*TimeToExpiration), 0) -> 22.02684 | E14: =Underlying*EXP(-DividendYield*TimeToExpiration) -> 339.25 | F14: 1.0600004 | G14: 1.0799999 | H14: =MAX(A14*EXP(-RiskFreeRate*TimeToExpiration)-Underlying*EXP(-DividendYield*TimeToExpiration), 0) -> 0 | I14: =A14*EXP(-RiskFreeRate*TimeToExpiration) -> 317.22316 | J14: =AVERAGE(B14:C14) -> 23.025002 | K14: =AVERAGE(F14:G14) -> 1.0700002 | L14: =C14-B14 -> 0.65000915 | M14: =G14-F14 -> 0.019999504
A15: 320 | B15: 20.850006 | C15: 21 | D15: =MAX(Underlying*EXP(-DividendYield*TimeToExpiration)-A15*EXP(-RiskFreeRate*TimeToExpiration), 0) -> 19.529019 | E15: =Underlying*EXP(-DividendYield*TimeToExpiration) -> 339.25 | F15: 1.3100004 | G15: 1.3299999 | H15: =MAX(A15*EXP(-RiskFreeRate*TimeToExpiration)-Underlying*EXP(-DividendYield*TimeToExpiration), 0) -> 0 | I15: =A15*EXP(-RiskFreeRate*TimeToExpiration) -> 319.72098 | J15: =AVERAGE(B15:C15) -> 20.925003 | K15: =AVERAGE(F15:G15) -> 1.3200002 | L15: =C15-B15 -> 0.1499939 | M15: =G15-F15 -> 0.019999504
A16: 322.5 | B16: 18.699997 | C16: 19.199997 | D16: =MAX(Underlying*EXP(-DividendYield*TimeToExpiration)-A16*EXP(-RiskFreeRate*TimeToExpiration), 0) -> 17.031199 | E16: =Underlying*EXP(-DividendYield*TimeToExpiration) -> 339.25 | F16: 1.6499996 | G16: 1.6799994 | H16: =MAX(A16*EXP(-RiskFreeRate*TimeToExpiration)-Underlying*EXP(-DividendYield*TimeToExpiration), 0) -> 0 | I16: =A16*EXP(-RiskFreeRate*TimeToExpiration) -> 322.2188 | J16: =AVERAGE(B16:C16) -> 18.949997 | K16: =AVERAGE(F16:G16) -> 1.6649995 | L16: =C16-B16 -> 0.5 | M16: =G16-F16 -> 0.029999733
... A39: 380 | B39: 0.33000004 | C39: 0.35000002 | D39: =MAX(Underlying*EXP(-DividendYield*TimeToExpiration)-A39*EXP(-RiskFreeRate*TimeToExpiration), 0) -> 0 | E39: =Underlying*EXP(-DividendYield*TimeToExpiration) -> 339.25 | F39: 40.350006 | G39: 41 | H39: =MAX(A39*EXP(-RiskFreeRate*TimeToExpiration)-Underlying*EXP(-DividendYield*TimeToExpiration), 0) -> 40.418665 | I39: =A39*EXP(-RiskFreeRate*TimeToExpiration) -> 379.66866 | J39: =AVERAGE(B39:C39) -> 0.34000003 | K39: =AVERAGE(F39:G39) -> 40.675003 | L39: =C39-B39 -> 0.019999981 | M39: =G39-F39 -> 0.6499939

Sheet Option Param Details
A2: Underlying | B2: 339.25
A3: Interest rate | B3: 0.04362
A4: Div yield | B4: 0
A5: As Of | B5: 45898.488
A6: Expiration | B6: 45905.688
A7: Days To Expiration | B7: =B6-B5 -> 7.1993056
A8: Day Count Convention | B8: 360
A9: Years To Expiration | B9: =B7/B8 -> 0.019998071
A11: Max Vola In Solvers | B11: 3
A12: Min Vola In Solvers | B12: 0.001

Sheet Call Vola Solver
B1: Iteration | I1: 0 | O1: =1+I1 -> 1 | U1: =1+O1 -> 2 | AA1: =1+U1 -> 3 | AG1: =1+AA1 -> 4 | AM1: =1+AG1 -> 5 | AS1: =1+AM1 -> 6 | AY1: =1+AS1 -> 7 | BE1: =1+AY1 -> 8 | BK1: =1+BE1 -> 9 | BQ1: =1+BK1 -> 10 | BW1: =1+BQ1 -> 11 | CC1: =1+BW1 -> 12 | CI1: =1+CC1 -> 13 | CO1: =1+CI1 -> 14 | CU1: =1+CO1 -> 15 | DA1: =1+CU1 -> 16
B2: CallPut ξ | I2: 1 | K2: =I2 -> 1 | L2: =K2 -> 1 | N2: =L2 -> 1 | O2: =I2 -> 1 | Q2: =O2 -> 1 | R2: =Q2 -> 1 | T2: =R2 -> 1 | U2: =O2 -> 1 | W2: =U2 -> 1 | X2: =W2 -> 1 | Z2: =X2 -> 1 | AA2: =U2 -> 1 | AC2: =AA2 -> 1 | AD2: =AC2 -> 1 | AF2: =AD2 -> 1 | AG2: =AA2 -> 1 | AI2: =AG2 -> 1 | AJ2: =AI2 -> 1 | AL2: =AJ2 -> 1 | AM2: =AG2 -> 1 | AO2: =AM2 -> 1 | AP2: =AO2 -> 1 | AR2: =AP2 -> 1 | AS2: =AM2 -> 1 | AU2: =AS2 -> 1 | AV2: =AU2 -> 1 | AX2: 1 | AY2: =AS2 -> 1 | BA2: =AY2 -> 1 | BB2: =BA2 -> 1 | BD2: =BB2 -> 1 | BE2: =AY2 -> 1 | BG2: =BE2 -> 1 | BH2: =BG2 -> 1 | BJ2: =BH2 -> 1 | BK2: =BE2 -> 1 | BM2: =BK2 -> 1 | BN2: =BM2 -> 1 | BP2: =BN2 -> 1 | BQ2: =BK2 -> 1 | BS2: =BQ2 -> 1 | BT2: =BS2 -> 1 | BV2: =BT2 -> 1 | BW2: =BQ2 -> 1 | BY2: =BW2 -> 1 | BZ2: =BY2 -> 1 | CB2: =BZ2 -> 1 | CC2: =BW2 -> 1 | CE2: =CC2 -> 1 | CF2: =CE2 -> 1 | CH2: =CF2 -> 1 | CI2: =CC2 -> 1 | CK2: =CI2 -> 1 | CL2: =CK2 -> 1 | CN2: =CL2 -> 1 | CO2: =CI2 -> 1 | CQ2: =CO2 -> 1 | CR2: =CQ2 -> 1 | CT2: =CR2 -> 1 | CU2: =CO2 -> 1 | CW2: =CU2 -> 1 | CX2: =CW2 -> 1 | CZ2: =CX2 -> 1 | DA2: =CU2 -> 1 | DC2: =DA2 -> 1 | DD2: =DC2 -> 1 | DF2: =DD2 -> 1
A4: Strike | B4: Final Vola | C4: Final Price | D4: Abs Price Err | E4: Relative Price Err | F4: Price Err/Spread | G4: Target Price | H4: Strike | I4: Vola Low | J4: Vola High | K4: Price Low | L4: Price High | M4: Test Vola | N4: New Price | O4: Vola Low | P4: Vola High | Q4: Price Low | R4: Price High | S4: Test Vola | T4: New Price | U4: Vola Low | V4: Vola High | W4: Price Low | X4: Price High | Y4: Test Vola | Z4: New Price | AA4: Vola Low | AB4: Vola High | AC4: Price Low | AD4: Price High | AE4: Test Vola | AF4: New Price | AG4: Vola Low | AH4: Vola High | AI4: Price Low | AJ4: Price High | AK4: Test Vola | AL4: New Price | AM4: Vola Low | AN4: Vola High | AO4: Price Low | AP4: Price High | AQ4: Test Vola | AR4: New Price | AS4: Vola Low | AT4: Vola High | AU4: Price Low | AV4: Price High | AW4: Test Vola | AX4: New Price | AY4: Vola Low | AZ4: Vola High | BA4: Price Low | BB4: Price High | BC4: Test Vola | BD4: New Price | BE4: Vola Low | BF4: Vola High | BG4: Price Low | BH4: Price High | BI4: Test Vola | BJ4: New Price | BK4: Vola Low | BL4: Vola High | BM4: Price Low | BN4: Price High | BO4: Test Vola | BP4: New Price | BQ4: Vola Low | BR4: Vola High | BS4: Price Low | BT4: Price High | BU4: Test Vola | BV4: New Price | BW4: Vola Low | BX4: Vola High | BY4: Price Low | BZ4: Price High | CA4: Test Vola | CB4: New Price | CC4: Vola Low | CD4: Vola High | CE4: Price Low | CF4: Price High | CG4: Test Vola | CH4: New Price | CI4: Vola Low | CJ4: Vola High | CK4: Price Low | CL4: Price High | CM4: Test Vola | CN4: New Price | CO4: Vola Low | CP4: Vola High | CQ4: Price Low | CR4: Price High | CS4: Test Vola | CT4: New Price | CU4: Vola Low | CV4: Vola High | CW4: Price Low | CX4: Price High | CY4: Test Vola | CZ4: New Price | DA4: Vola Low | DB4: Vola High | DC4: Price Low | DD4: Price High | DE4: Test Vola | DF4: New Price
A5: ='Option Mkt Data'!A5 -> 295 | B5: =DE5 -> 0.60529832 | C5: =DF5 -> 45.074915 | D5: =ABS(C5-G5) -> 8.1879191e-05 | E5: =D5/G5 -> 1.8165102e-06 | F5: =D5/'Option Mkt Data'!L5 -> 0.00010917225 | G5: ='Option Mkt Data'!J5 -> 45.074997 | H5: ='Option Mkt Data'!A5 -> 295 | I5: =MinSolverVola -> 0.001 | J5: =MaxSolverVola -> 3 | K5: =K$2*(Underlying*EXP(-DividendYield*TimeToExpiration)*_xlfn.NORM.DIST(K$2*(LN(Underlying/$H5)+(RiskFreeRate-DividendYield+0.5*I5^2)*TimeToExpiration)/(I5*TimeToExpiration^0.5), 0, 1, TRUE) - $H5*EXP(-RiskFreeRate*TimeToExpiration)*_xlfn.NORM.DIST(K$2*(LN(Underlying/$H5)+(RiskFreeRate-DividendYield-0.5*I5^2)*TimeToExpiration)/(I5*TimeToExpiration^0.5), 0, 1, TRUE) ) -> 44.507221 | L5: =L$2*(Underlying*EXP(-DividendYield*TimeToExpiration)*_xlfn.NORM.DIST(L$2*(LN(Underlying/$H5)+(RiskFreeRate-DividendYield+0.5*J5^2)*TimeToExpiration)/(J5*TimeToExpiration^0.5), 0, 1, TRUE) - $H5*EXP(-RiskFreeRate*TimeToExpiration)*_xlfn.NORM.DIST(L$2*(LN(Underlying/$H5)+(RiskFreeRate-DividendYield-0.5*J5^2)*TimeToExpiration)/(J5*TimeToExpiration^0.5), 0, 1, TRUE) ) -> 78.355468 | M5: =(I5+J5)/2 -> 1.5005 | N5: =N$2*(Underlying*EXP(-DividendYield*TimeToExpiration)*_xlfn.NORM.DIST(N$2*(LN(Underlying/$H5)+(RiskFreeRate-DividendYield+0.5*M5^2)*TimeToExpiration)/(M5*TimeToExpiration^0.5), 0, 1, TRUE) - $H5*EXP(-RiskFreeRate*TimeToExpiration)*_xlfn.NORM.DIST(N$2*(LN(Underlying/$H5)+(RiskFreeRate-DividendYield-0.5*M5^2)*TimeToExpiration)/(M5*TimeToExpiration^0.5), 0, 1, TRUE) ) -> 54.681473 | O5: =IF(N5>$G5, I5, M5) -> 0.001 | P5: =IF(N5>$G5, M5, J5) -> 1.5005 | Q5: =Q$2*(Underlying*EXP(-DividendYield*TimeToExpiration)*_xlfn.NORM.DIST(Q$2*(LN(Underlying/$H5)+(RiskFreeRate-DividendYield+0.5*O5^2)*TimeToExpiration)/(O5*TimeToExpiration^0.5), 0, 1, TRUE) - $H5*EXP(-RiskFreeRate*TimeToExpiration)*_xlfn.NORM.DIST(Q$2*(LN(Underlying/$H5)+(RiskFreeRate-DividendYield-0.5*O5^2)*TimeToExpiration)/(O5*TimeToExpiration^0.5), 0, 1, TRUE)) -> 44.507221 | R5: =R$2*(Underlying*EXP(-DividendYield*TimeToExpiration)*_xlfn.NORM.DIST(R$2*(LN(Underlying/$H5)+(RiskFreeRate-DividendYield+0.5*P5^2)*TimeToExpiration)/(P5*TimeToExpiration^0.5), 0, 1, TRUE) - $H5*EXP(-RiskFreeRate*TimeToExpiration)*_xlfn.NORM.DIST(R$2*(LN(Underlying/$H5)+(RiskFreeRate-DividendYield-0.5*P5^2)*TimeToExpiration)/(P5*TimeToExpiration^0.5), 0, 1, TRUE) ) -> 54.681473 | S5: =(O5+P5)/2 -> 0.75075 | T5: =T$2*(Underlying*EXP(-DividendYield*TimeToExpiration)*_xlfn.NORM.DIST(T$2*(LN(Underlying/$H5)+(RiskFreeRate-DividendYield+0.5*S5^2)*TimeToExpiration)/(S5*TimeToExpiration^0.5), 0, 1, TRUE) - $H5*EXP(-RiskFreeRate*TimeToExpiration)*_xlfn.NORM.DIST(T$2*(LN(Underlying/$H5)+(RiskFreeRate-DividendYield-0.5*S5^2)*TimeToExpiration)/(S5*TimeToExpiration^0.5), 0, 1, TRUE) ) -> 45.955861 | U5: =IF(T5>$G5, O5, S5) -> 0.001 | V5: =IF(T5>$G5, S5, P5) -> 0.75075 | W5: =W$2*(Underlying*EXP(-DividendYield*TimeToExpiration)*_xlfn.NORM.DIST(W$2*(LN(Underlying/$H5)+(RiskFreeRate-DividendYield+0.5*U5^2)*TimeToExpiration)/(U5*TimeToExpiration^0.5), 0, 1, TRUE) - $H5*EXP(-RiskFreeRate*TimeToExpiration)*_xlfn.NORM.DIST(W$2*(LN(Underlying/$H5)+(RiskFreeRate-DividendYield-0.5*U5^2)*TimeToExpiration)/(U5*TimeToExpiration^0.5), 0, 1, TRUE) ) -> 44.507221 | X5: =X$2*(Underlying*EXP(-DividendYield*TimeToExpiration)*_xlfn.NORM.DIST(X$2*(LN(Underlying/$H5)+(RiskFreeRate-DividendYield+0.5*V5^2)*TimeToExpiration)/(V5*TimeToExpiration^0.5), 0, 1, TRUE) - $H5*EXP(-RiskFreeRate*TimeToExpiration)*_xlfn.NORM.DIST(X$2*(LN(Underlying/$H5)+(RiskFreeRate-DividendYield-0.5*V5^2)*TimeToExpiration)/(V5*TimeToExpiration^0.5), 0, 1, TRUE) ) -> 45.955861 | Y5: =(U5+V5)/2 -> 0.375875 | Z5: =Z$2*(Underlying*EXP(-DividendYield*TimeToExpiration)*_xlfn.NORM.DIST(Z$2*(LN(Underlying/$H5)+(RiskFreeRate-DividendYield+0.5*Y5^2)*TimeToExpiration)/(Y5*TimeToExpiration^0.5), 0, 1, TRUE) - $H5*EXP(-RiskFreeRate*TimeToExpiration)*_xlfn.NORM.DIST(Z$2*(LN(Underlying/$H5)+(RiskFreeRate-DividendYield-0.5*Y5^2)*TimeToExpiration)/(Y5*TimeToExpiration^0.5), 0, 1, TRUE) ) -> 44.528463 | AA5: =IF(Z5>$G5, U5, Y5) -> 0.375875 | AB5: =IF(Z5>$G5, Y5, V5) -> 0.75075 | AC5: =AC$2*(Underlying*EXP(-DividendYield*TimeToExpiration)*_xlfn.NORM.DIST(AC$2*(LN(Underlying/$H5)+(RiskFreeRate-DividendYield+0.5*AA5^2)*TimeToExpiration)/(AA5*TimeToExpiration^0.5), 0, 1, TRUE) - $H5*EXP(-RiskFreeRate*TimeToExpiration)*_xlfn.NORM.DIST(AC$2*(LN(Underlying/$H5)+(RiskFreeRate-DividendYield-0.5*AA5^2)*TimeToExpiration)/(AA5*TimeToExpiration^0.5), 0, 1, TRUE) ) -> 44.528463 | AD5: =AD$2*(Underlying*EXP(-DividendYield*TimeToExpiration)*_xlfn.NORM.DIST(AD$2*(LN(Underlying/$H5)+(RiskFreeRate-DividendYield+0.5*AB5^2)*TimeToExpiration)/(AB5*TimeToExpiration^0.5), 0, 1, TRUE) - $H5*EXP(-RiskFreeRate*TimeToExpiration)*_xlfn.NORM.DIST(AD$2*(LN(Underlying/$H5)+(RiskFreeRate-DividendYield-0.5*AB5^2)*TimeToExpiration)/(AB5*TimeToExpiration^0.5), 0, 1, TRUE) ) -> 45.955861 | AE5: =(AA5+AB5)/2 -> 0.5633125 | AF5: =AF$2*(Underlying*EXP(-DividendYield*TimeToExpiration)*_xlfn.NORM.DIST(AF$2*(LN(Underlying/$H5)+(RiskFreeRate-DividendYield+0.5*AE5^2)*TimeToExpiration)/(AE5*TimeToExpiration^0.5), 0, 1, TRUE) - $H5*EXP(-RiskFreeRate*TimeToExpiration)*_xlfn.NORM.DIST(AF$2*(LN(Underlying/$H5)+(RiskFreeRate-DividendYield-0.5*AE5^2)*TimeToExpiration)/(AE5*TimeToExpiration^0.5), 0, 1, TRUE) ) -> 44.899097 | AG5: =IF(AF5>$G5, AA5, AE5) -> 0.5633125 | AH5: =IF(AF5>$G5, AE5, AB5) -> 0.75075 | AI5: =AI$2*(Underlying*EXP(-DividendYield*TimeToExpiration)*_xlfn.NORM.DIST(AI$2*(LN(Underlying/$H5)+(RiskFreeRate-DividendYield+0.5*AG5^2)*TimeToExpiration)/(AG5*TimeToExpiration^0.5), 0, 1, TRUE) - $H5*EXP(-RiskFreeRate*TimeToExpiration)*_xlfn.NORM.DIST(AI$2*(LN(Underlying/$H5)+(RiskFreeRate-DividendYield-0.5*AG5^2)*TimeToExpiration)/(AG5*TimeToExpiration^0.5), 0, 1, TRUE) ) -> 44.899097 | AJ5: =AJ$2*(Underlying*EXP(-DividendYield*TimeToExpiration)*_xlfn.NORM.DIST(AJ$2*(LN(Underlying/$H5)+(RiskFreeRate-DividendYield+0.5*AH5^2)*TimeToExpiration)/(AH5*TimeToExpiration^0.5), 0, 1, TRUE) - $H5*EXP(-RiskFreeRate*TimeToExpiration)*_xlfn.NORM.DIST(AJ$2*(LN(Underlying/$H5)+(RiskFreeRate-DividendYield-0.5*AH5^2)*TimeToExpiration)/(AH5*TimeToExpiration^0.5), 0, 1, TRUE) ) -> 45.955861 | AK5: =(AG5+AH5)/2 -> 0.65703125 | AL5: =AL$2*(Underlying*EXP(-DividendYield*TimeToExpiration)*_xlfn.NORM.DIST(AL$2*(LN(Underlying/$H5)+(RiskFreeRate-DividendYield+0.5*AK5^2)*TimeToExpiration)/(AK5*TimeToExpiration^0.5), 0, 1, TRUE) - $H5*EXP(-RiskFreeRate*TimeToExpiration)*_xlfn.NORM.DIST(AL$2*(LN(Underlying/$H5)+(RiskFreeRate-DividendYield-0.5*AK5^2)*TimeToExpiration)/(AK5*TimeToExpiration^0.5), 0, 1, TRUE) ) -> 45.341276 | AM5: =IF(AL5>$G5, AG5, AK5) -> 0.5633125 | AN5: =IF(AL5>$G5, AK5, AH5) -> 0.65703125 | AO5: =AO$2*(Underlying*EXP(-DividendYield*TimeToExpiration)*_xlfn.NORM.DIST(AO$2*(LN(Underlying/$H5)+(RiskFreeRate-DividendYield+0.5*AM5^2)*TimeToExpiration)/(AM5*TimeToExpiration^0.5), 0, 1, TRUE) - $H5*EXP(-RiskFreeRate*TimeToExpiration)*_xlfn.NORM.DIST(AO$2*(LN(Underlying/$H5)+(RiskFreeRate-DividendYield-0.5*AM5^2)*TimeToExpiration)/(AM5*TimeToExpiration^0.5), 0, 1, TRUE) ) -> 44.899097 | AP5: =AP$2*(Underlying*EXP(-DividendYield*TimeToExpiration)*_xlfn.NORM.DIST(AP$2*(LN(Underlying/$H5)+(RiskFreeRate-DividendYield+0.5*AN5^2)*TimeToExpiration)/(AN5*TimeToExpiration^0.5), 0, 1, TRUE) - $H5*EXP(-RiskFreeRate*TimeToExpiration)*_xlfn.NORM.DIST(AP$2*(LN(Underlying/$H5)+(RiskFreeRate-DividendYield-0.5*AN5^2)*TimeToExpiration)/(AN5*TimeToExpiration^0.5), 0, 1, TRUE) ) -> 45.341276 | AQ5: =(AM5+AN5)/2 -> 0.61017188 | AR5: =AR$2*(Underlying*EXP(-DividendYield*TimeToExpiration)*_xlfn.NORM.DIST(AR$2*(LN(Underlying/$H5)+(RiskFreeRate-DividendYield+0.5*AQ5^2)*TimeToExpiration)/(AQ5*TimeToExpiration^0.5), 0, 1, TRUE) - $H5*EXP(-RiskFreeRate*TimeToExpiration)*_xlfn.NORM.DIST(AR$2*(LN(Underlying/$H5)+(RiskFreeRate-DividendYield-0.5*AQ5^2)*TimeToExpiration)/(AQ5*TimeToExpiration^0.5), 0, 1, TRUE) ) -> 45.097685 | AS5: =IF(AR5>$G5, AM5, AQ5) -> 0.5633125 | AT5: =IF(AR5>$G5, AQ5, AN5) -> 0.61017188 | AU5: =AU$2*(Underlying*EXP(-DividendYield*TimeToExpiration)*_xlfn.NORM.DIST(AU$2*(LN(Underlying/$H5)+(RiskFreeRate-DividendYield+0.5*AS5^2)*TimeToExpiration)/(AS5*TimeToExpiration^0.5), 0, 1, TRUE) - $H5*EXP(-RiskFreeRate*TimeToExpiration)*_xlfn.NORM.DIST(AU$2*(LN(Underlying/$H5)+(RiskFreeRate-DividendYield-0.5*AS5^2)*TimeToExpiration)/(AS5*TimeToExpiration^0.5), 0, 1, TRUE) ) -> 44.899097 | AV5: =AV$2*(Underlying*EXP(-DividendYield*TimeToExpiration)*_xlfn.NORM.DIST(AV$2*(LN(Underlying/$H5)+(RiskFreeRate-DividendYield+0.5*AT5^2)*TimeToExpiration)/(AT5*TimeToExpiration^0.5), 0, 1, TRUE) - $H5*EXP(-RiskFreeRate*TimeToExpiration)*_xlfn.NORM.DIST(AV$2*(LN(Underlying/$H5)+(RiskFreeRate-DividendYield-0.5*AT5^2)*TimeToExpiration)/(AT5*TimeToExpiration^0.5), 0, 1, TRUE) ) -> 45.097685 | AW5: =(AS5+AT5)/2 -> 0.58674219 | AX5: =AX$2*(Underlying*EXP(-DividendYield*TimeToExpiration)*_xlfn.NORM.DIST(AX$2*(LN(Underlying/$H5)+(RiskFreeRate-DividendYield+0.5*AW5^2)*TimeToExpiration)/(AW5*TimeToExpiration^0.5), 0, 1, TRUE) - $H5*EXP(-RiskFreeRate*TimeToExpiration)*_xlfn.NORM.DIST(AX$2*(LN(Underlying/$H5)+(RiskFreeRate-DividendYield-0.5*AW5^2)*TimeToExpiration)/(AW5*TimeToExpiration^0.5), 0, 1, TRUE) ) -> 44.992703 | AY5: =IF(AX5>$G5, AS5, AW5) -> 0.58674219 | AZ5: =IF(AX5>$G5, AW5, AT5) -> 0.61017188 | BA5: =BA$2*(Underlying*EXP(-DividendYield*TimeToExpiration)*_xlfn.NORM.DIST(BA$2*(LN(Underlying/$H5)+(RiskFreeRate-DividendYield+0.5*AY5^2)*TimeToExpiration)/(AY5*TimeToExpiration^0.5), 0, 1, TRUE) - $H5*EXP(-RiskFreeRate*TimeToExpiration)*_xlfn.NORM.DIST(BA$2*(LN(Underlying/$H5)+(RiskFreeRate-DividendYield-0.5*AY5^2)*TimeToExpiration)/(AY5*TimeToExpiration^0.5), 0, 1, TRUE) ) -> 44.992703 | BB5: =BB$2*(Underlying*EXP(-DividendYield*TimeToExpiration)*_xlfn.NORM.DIST(BB$2*(LN(Underlying/$H5)+(RiskFreeRate-DividendYield+0.5*AZ5^2)*TimeToExpiration)/(AZ5*TimeToExpiration^0.5), 0, 1, TRUE) - $H5*EXP(-RiskFreeRate*TimeToExpiration)*_xlfn.NORM.DIST(BB$2*(LN(Underlying/$H5)+(RiskFreeRate-DividendYield-0.5*AZ5^2)*TimeToExpiration)/(AZ5*TimeToExpiration^0.5), 0, 1, TRUE) ) -> 45.097685 | BC5: =(AY5+AZ5)/2 -> 0.59845703 | BD5: =BD$2*(Underlying*EXP(-DividendYield*TimeToExpiration)*_xlfn.NORM.DIST(BD$2*(LN(Underlying/$H5)+(RiskFreeRate-DividendYield+0.5*BC5^2)*TimeToExpiration)/(BC5*TimeToExpiration^0.5), 0, 1, TRUE) - $H5*EXP(-RiskFreeRate*TimeToExpiration)*_xlfn.NORM.DIST(BD$2*(LN(Underlying/$H5)+(RiskFreeRate-DividendYield-0.5*BC5^2)*TimeToExpiration)/(BC5*TimeToExpiration^0.5), 0, 1, TRUE) ) -> 45.043777 | BE5: =IF(BD5>$G5, AY5, BC5) -> 0.59845703 | BF5: =IF(BD5>$G5, BC5, AZ5) -> 0.61017188 | BG5: =BG$2*(Underlying*EXP(-DividendYield*TimeToExpiration)*_xlfn.NORM.DIST(BG$2*(LN(Underlying/$H5)+(RiskFreeRate-DividendYield+0.5*BE5^2)*TimeToExpiration)/(BE5*TimeToExpiration^0.5), 0, 1, TRUE) - $H5*EXP(-RiskFreeRate*TimeToExpiration)*_xlfn.NORM.DIST(BG$2*(LN(Underlying/$H5)+(RiskFreeRate-DividendYield-0.5*BE5^2)*TimeToExpiration)/(BE5*TimeToExpiration^0.5), 0, 1, TRUE) ) -> 45.043777 | BH5: =BH$2*(Underlying*EXP(-DividendYield*TimeToExpiration)*_xlfn.NORM.DIST(BH$2*(LN(Underlying/$H5)+(RiskFreeRate-DividendYield+0.5*BF5^2)*TimeToExpiration)/(BF5*TimeToExpiration^0.5), 0, 1, TRUE) - $H5*EXP(-RiskFreeRate*TimeToExpiration)*_xlfn.NORM.DIST(BH$2*(LN(Underlying/$H5)+(RiskFreeRate-DividendYield-0.5*BF5^2)*TimeToExpiration)/(BF5*TimeToExpiration^0.5), 0, 1, TRUE) ) -> 45.097685 | BI5: =(BE5+BF5)/2 -> 0.60431445 | BJ5: =BJ$2*(Underlying*EXP(-DividendYield*TimeToExpiration)*_xlfn.NORM.DIST(BJ$2*(LN(Underlying/$H5)+(RiskFreeRate-DividendYield+0.5*BI5^2)*TimeToExpiration)/(BI5*TimeToExpiration^0.5), 0, 1, TRUE) - $H5*EXP(-RiskFreeRate*TimeToExpiration)*_xlfn.NORM.DIST(BJ$2*(LN(Underlying/$H5)+(RiskFreeRate-DividendYield-0.5*BI5^2)*TimeToExpiration)/(BI5*TimeToExpiration^0.5), 0, 1, TRUE) ) -> 45.070378 | BK5: =IF(BJ5>$G5, BE5, BI5) -> 0.60431445 | BL5: =IF(BJ5>$G5, BI5, BF5) -> 0.61017188 | BM5: =BM$2*(Underlying*EXP(-DividendYield*TimeToExpiration)*_xlfn.NORM.DIST(BM$2*(LN(Underlying/$H5)+(RiskFreeRate-DividendYield+0.5*BK5^2)*TimeToExpiration)/(BK5*TimeToExpiration^0.5), 0, 1, TRUE) - $H5*EXP(-RiskFreeRate*TimeToExpiration)*_xlfn.NORM.DIST(BM$2*(LN(Underlying/$H5)+(RiskFreeRate-DividendYield-0.5*BK5^2)*TimeToExpiration)/(BK5*TimeToExpiration^0.5), 0, 1, TRUE) ) -> 45.070378 | BN5: =BN$2*(Underlying*EXP(-DividendYield*TimeToExpiration)*_xlfn.NORM.DIST(BN$2*(LN(Underlying/$H5)+(RiskFreeRate-DividendYield+0.5*BL5^2)*TimeToExpiration)/(BL5*TimeToExpiration^0.5), 0, 1, TRUE) - $H5*EXP(-RiskFreeRate*TimeToExpiration)*_xlfn.NORM.DIST(BN$2*(LN(Underlying/$H5)+(RiskFreeRate-DividendYield-0.5*BL5^2)*TimeToExpiration)/(BL5*TimeToExpiration^0.5), 0, 1, TRUE) ) -> 45.097685 | BO5: =(BK5+BL5)/2 -> 0.60724316 | BP5: =BP$2*(Underlying*EXP(-DividendYield*TimeToExpiration)*_xlfn.NORM.DIST(BP$2*(LN(Underlying/$H5)+(RiskFreeRate-DividendYield+0.5*BO5^2)*TimeToExpiration)/(BO5*TimeToExpiration^0.5), 0, 1, TRUE) - $H5*EXP(-RiskFreeRate*TimeToExpiration)*_xlfn.NORM.DIST(BP$2*(LN(Underlying/$H5)+(RiskFreeRate-DividendYield-0.5*BO5^2)*TimeToExpiration)/(BO5*TimeToExpiration^0.5), 0, 1, TRUE) ) -> 45.083943 | BQ5: =IF(BP5>$G5, BK5, BO5) -> 0.60431445 | BR5: =IF(BP5>$G5, BO5, BL5) -> 0.60724316 | BS5: =BS$2*(Underlying*EXP(-DividendYield*TimeToExpiration)*_xlfn.NORM.DIST(BS$2*(LN(Underlying/$H5)+(RiskFreeRate-DividendYield+0.5*BQ5^2)*TimeToExpiration)/(BQ5*TimeToExpiration^0.5), 0, 1, TRUE) - $H5*EXP(-RiskFreeRate*TimeToExpiration)*_xlfn.NORM.DIST(BS$2*(LN(Underlying/$H5)+(RiskFreeRate-DividendYield-0.5*BQ5^2)*TimeToExpiration)/(BQ5*TimeToExpiration^0.5), 0, 1, TRUE) ) -> 45.070378 | BT5: =BT$2*(Underlying*EXP(-DividendYield*TimeToExpiration)*_xlfn.NORM.DIST(BT$2*(LN(Underlying/$H5)+(RiskFreeRate-DividendYield+0.5*BR5^2)*TimeToExpiration)/(BR5*TimeToExpiration^0.5), 0, 1, TRUE) - $H5*EXP(-RiskFreeRate*TimeToExpiration)*_xlfn.NORM.DIST(BT$2*(LN(Underlying/$H5)+(RiskFreeRate-DividendYield-0.5*BR5^2)*TimeToExpiration)/(BR5*TimeToExpiration^0.5), 0, 1, TRUE) ) -> 45.083943 | BU5: =(BQ5+BR5)/2 -> 0.60577881 | BV5: =BV$2*(Underlying*EXP(-DividendYield*TimeToExpiration)*_xlfn.NORM.DIST(BV$2*(LN(Underlying/$H5)+(RiskFreeRate-DividendYield+0.5*BU5^2)*TimeToExpiration)/(BU5*TimeToExpiration^0.5), 0, 1, TRUE) - $H5*EXP(-RiskFreeRate*TimeToExpiration)*_xlfn.NORM.DIST(BV$2*(LN(Underlying/$H5)+(RiskFreeRate-DividendYield-0.5*BU5^2)*TimeToExpiration)/(BU5*TimeToExpiration^0.5), 0, 1, TRUE) ) -> 45.077138 | BW5: =IF(BV5>$G5, BQ5, BU5) -> 0.60431445 | BX5: =IF(BV5>$G5, BU5, BR5) -> 0.60577881 | BY5: =BY$2*(Underlying*EXP(-DividendYield*TimeToExpiration)*_xlfn.NORM.DIST(BY$2*(LN(Underlying/$H5)+(RiskFreeRate-DividendYield+0.5*BW5^2)*TimeToExpiration)/(BW5*TimeToExpiration^0.5), 0, 1, TRUE) - $H5*EXP(-RiskFreeRate*TimeToExpiration)*_xlfn.NORM.DIST(BY$2*(LN(Underlying/$H5)+(RiskFreeRate-DividendYield-0.5*BW5^2)*TimeToExpiration)/(BW5*TimeToExpiration^0.5), 0, 1, TRUE) ) -> 45.070378 | BZ5: =BZ$2*(Underlying*EXP(-DividendYield*TimeToExpiration)*_xlfn.NORM.DIST(BZ$2*(LN(Underlying/$H5)+(RiskFreeRate-DividendYield+0.5*BX5^2)*TimeToExpiration)/(BX5*TimeToExpiration^0.5), 0, 1, TRUE) - $H5*EXP(-RiskFreeRate*TimeToExpiration)*_xlfn.NORM.DIST(BZ$2*(LN(Underlying/$H5)+(RiskFreeRate-DividendYield-0.5*BX5^2)*TimeToExpiration)/(BX5*TimeToExpiration^0.5), 0, 1, TRUE) ) -> 45.077138 | CA5: =(BW5+BX5)/2 -> 0.60504663 | CB5: =CB$2*(Underlying*EXP(-DividendYield*TimeToExpiration)*_xlfn.NORM.DIST(CB$2*(LN(Underlying/$H5)+(RiskFreeRate-DividendYield+0.5*CA5^2)*TimeToExpiration)/(CA5*TimeToExpiration^0.5), 0, 1, TRUE) - $H5*EXP(-RiskFreeRate*TimeToExpiration)*_xlfn.NORM.DIST(CB$2*(LN(Underlying/$H5)+(RiskFreeRate-DividendYield-0.5*CA5^2)*TimeToExpiration)/(CA5*TimeToExpiration^0.5), 0, 1, TRUE) ) -> 45.073752 | CC5: =IF(CB5>$G5, BW5, CA5) -> 0.60504663 | CD5: =IF(CB5>$G5, CA5, BX5) -> 0.60577881 | CE5: =CE$2*(Underlying*EXP(-DividendYield*TimeToExpiration)*_xlfn.NORM.DIST(CE$2*(LN(Underlying/$H5)+(RiskFreeRate-DividendYield+0.5*CC5^2)*TimeToExpiration)/(CC5*TimeToExpiration^0.5), 0, 1, TRUE) - $H5*EXP(-RiskFreeRate*TimeToExpiration)*_xlfn.NORM.DIST(CE$2*(LN(Underlying/$H5)+(RiskFreeRate-DividendYield-0.5*CC5^2)*TimeToExpiration)/(CC5*TimeToExpiration^0.5), 0, 1, TRUE) ) -> 45.073752 | CF5: =CF$2*(Underlying*EXP(-DividendYield*TimeToExpiration)*_xlfn.NORM.DIST(CF$2*(LN(Underlying/$H5)+(RiskFreeRate-DividendYield+0.5*CD5^2)*TimeToExpiration)/(CD5*TimeToExpiration^0.5), 0, 1, TRUE) - $H5*EXP(-RiskFreeRate*TimeToExpiration)*_xlfn.NORM.DIST(CF$2*(LN(Underlying/$H5)+(RiskFreeRate-DividendYield-0.5*CD5^2)*TimeToExpiration)/(CD5*TimeToExpiration^0.5), 0, 1, TRUE) ) -> 45.077138 | CG5: =(CC5+CD5)/2 -> 0.60541272 | CH5: =CH$2*(Underlying*EXP(-DividendYield*TimeToExpiration)*_xlfn.NORM.DIST(CH$2*(LN(Underlying/$H5)+(RiskFreeRate-DividendYield+0.5*CG5^2)*TimeToExpiration)/(CG5*TimeToExpiration^0.5), 0, 1, TRUE) - $H5*EXP(-RiskFreeRate*TimeToExpiration)*_xlfn.NORM.DIST(CH$2*(LN(Underlying/$H5)+(RiskFreeRate-DividendYield-0.5*CG5^2)*TimeToExpiration)/(CG5*TimeToExpiration^0.5), 0, 1, TRUE) ) -> 45.075444 | CI5: =IF(CH5>$G5, CC5, CG5) -> 0.60504663 | CJ5: =IF(CH5>$G5, CG5, CD5) -> 0.60541272 | CK5: =CK$2*(Underlying*EXP(-DividendYield*TimeToExpiration)*_xlfn.NORM.DIST(CK$2*(LN(Underlying/$H5)+(RiskFreeRate-DividendYield+0.5*CI5^2)*TimeToExpiration)/(CI5*TimeToExpiration^0.5), 0, 1, TRUE) - $H5*EXP(-RiskFreeRate*TimeToExpiration)*_xlfn.NORM.DIST(CK$2*(LN(Underlying/$H5)+(RiskFreeRate-DividendYield-0.5*CI5^2)*TimeToExpiration)/(CI5*TimeToExpiration^0.5), 0, 1, TRUE) ) -> 45.073752 | CL5: =CL$2*(Underlying*EXP(-DividendYield*TimeToExpiration)*_xlfn.NORM.DIST(CL$2*(LN(Underlying/$H5)+(RiskFreeRate-DividendYield+0.5*CJ5^2)*TimeToExpiration)/(CJ5*TimeToExpiration^0.5), 0, 1, TRUE) - $H5*EXP(-RiskFreeRate*TimeToExpiration)*_xlfn.NORM.DIST(CL$2*(LN(Underlying/$H5)+(RiskFreeRate-DividendYield-0.5*CJ5^2)*TimeToExpiration)/(CJ5*TimeToExpiration^0.5), 0, 1, TRUE) ) -> 45.075444 | CM5: =(CI5+CJ5)/2 -> 0.60522968 | CN5: =CN$2*(Underlying*EXP(-DividendYield*TimeToExpiration)*_xlfn.NORM.DIST(CN$2*(LN(Underlying/$H5)+(RiskFreeRate-DividendYield+0.5*CM5^2)*TimeToExpiration)/(CM5*TimeToExpiration^0.5), 0, 1, TRUE) - $H5*EXP(-RiskFreeRate*TimeToExpiration)*_xlfn.NORM.DIST(CN$2*(LN(Underlying/$H5)+(RiskFreeRate-DividendYield-0.5*CM5^2)*TimeToExpiration)/(CM5*TimeToExpiration^0.5), 0, 1, TRUE) ) -> 45.074598 | CO5: =IF(CN5>$G5, CI5, CM5) -> 0.60522968 | CP5: =IF(CN5>$G5, CM5, CJ5) -> 0.60541272 | CQ5: =CQ$2*(Underlying*EXP(-DividendYield*TimeToExpiration)*_xlfn.NORM.DIST(CQ$2*(LN(Underlying/$H5)+(RiskFreeRate-DividendYield+0.5*CO5^2)*TimeToExpiration)/(CO5*TimeToExpiration^0.5), 0, 1, TRUE) - $H5*EXP(-RiskFreeRate*TimeToExpiration)*_xlfn.NORM.DIST(CQ$2*(LN(Underlying/$H5)+(RiskFreeRate-DividendYield-0.5*CO5^2)*TimeToExpiration)/(CO5*TimeToExpiration^0.5), 0, 1, TRUE) ) -> 45.074598 | CR5: =CR$2*(Underlying*EXP(-DividendYield*TimeToExpiration)*_xlfn.NORM.DIST(CR$2*(LN(Underlying/$H5)+(RiskFreeRate-DividendYield+0.5*CP5^2)*TimeToExpiration)/(CP5*TimeToExpiration^0.5), 0, 1, TRUE) - $H5*EXP(-RiskFreeRate*TimeToExpiration)*_xlfn.NORM.DIST(CR$2*(LN(Underlying/$H5)+(RiskFreeRate-DividendYield-0.5*CP5^2)*TimeToExpiration)/(CP5*TimeToExpiration^0.5), 0, 1, TRUE) ) -> 45.075444 | CS5: =(CO5+CP5)/2 -> 0.6053212 | CT5: =CT$2*(Underlying*EXP(-DividendYield*TimeToExpiration)*_xlfn.NORM.DIST(CT$2*(LN(Underlying/$H5)+(RiskFreeRate-DividendYield+0.5*CS5^2)*TimeToExpiration)/(CS5*TimeToExpiration^0.5), 0, 1, TRUE) - $H5*EXP(-RiskFreeRate*TimeToExpiration)*_xlfn.NORM.DIST(CT$2*(LN(Underlying/$H5)+(RiskFreeRate-DividendYield-0.5*CS5^2)*TimeToExpiration)/(CS5*TimeToExpiration^0.5), 0, 1, TRUE) ) -> 45.075021 | CU5: =IF(CT5>$G5, CO5, CS5) -> 0.60522968 | CV5: =IF(CT5>$G5, CS5, CP5) -> 0.6053212 | CW5: =CW$2*(Underlying*EXP(-DividendYield*TimeToExpiration)*_xlfn.NORM.DIST(CW$2*(LN(Underlying/$H5)+(RiskFreeRate-DividendYield+0.5*CU5^2)*TimeToExpiration)/(CU5*TimeToExpiration^0.5), 0, 1, TRUE) - $H5*EXP(-RiskFreeRate*TimeToExpiration)*_xlfn.NORM.DIST(CW$2*(LN(Underlying/$H5)+(RiskFreeRate-DividendYield-0.5*CU5^2)*TimeToExpiration)/(CU5*TimeToExpiration^0.5), 0, 1, TRUE) ) -> 45.074598 | CX5: =CX$2*(Underlying*EXP(-DividendYield*TimeToExpiration)*_xlfn.NORM.DIST(CX$2*(LN(Underlying/$H5)+(RiskFreeRate-DividendYield+0.5*CV5^2)*TimeToExpiration)/(CV5*TimeToExpiration^0.5), 0, 1, TRUE) - $H5*EXP(-RiskFreeRate*TimeToExpiration)*_xlfn.NORM.DIST(CX$2*(LN(Underlying/$H5)+(RiskFreeRate-DividendYield-0.5*CV5^2)*TimeToExpiration)/(CV5*TimeToExpiration^0.5), 0, 1, TRUE) ) -> 45.075021 | CY5: =(CU5+CV5)/2 -> 0.60527544 | CZ5: =CZ$2*(Underlying*EXP(-DividendYield*TimeToExpiration)*_xlfn.NORM.DIST(CZ$2*(LN(Underlying/$H5)+(RiskFreeRate-DividendYield+0.5*CY5^2)*TimeToExpiration)/(CY5*TimeToExpiration^0.5), 0, 1, TRUE) - $H5*EXP(-RiskFreeRate*TimeToExpiration)*_xlfn.NORM.DIST(CZ$2*(LN(Underlying/$H5)+(RiskFreeRate-DividendYield-0.5*CY5^2)*TimeToExpiration)/(CY5*TimeToExpiration^0.5), 0, 1, TRUE) ) -> 45.074809 | DA5: =IF(CZ5>$G5, CU5, CY5) -> 0.60527544 | DB5: =IF(CZ5>$G5, CY5, CV5) -> 0.6053212 | DC5: =DC$2*(Underlying*EXP(-DividendYield*TimeToExpiration)*_xlfn.NORM.DIST(DC$2*(LN(Underlying/$H5)+(RiskFreeRate-DividendYield+0.5*DA5^2)*TimeToExpiration)/(DA5*TimeToExpiration^0.5), 0, 1, TRUE) - $H5*EXP(-RiskFreeRate*TimeToExpiration)*_xlfn.NORM.DIST(DC$2*(LN(Underlying/$H5)+(RiskFreeRate-DividendYield-0.5*DA5^2)*TimeToExpiration)/(DA5*TimeToExpiration^0.5), 0, 1, TRUE) ) -> 45.074809 | DD5: =DD$2*(Underlying*EXP(-DividendYield*TimeToExpiration)*_xlfn.NORM.DIST(DD$2*(LN(Underlying/$H5)+(RiskFreeRate-DividendYield+0.5*DB5^2)*TimeToExpiration)/(DB5*TimeToExpiration^0.5), 0, 1, TRUE) - $H5*EXP(-RiskFreeRate*TimeToExpiration)*_xlfn.NORM.DIST(DD$2*(LN(Underlying/$H5)+(RiskFreeRate-DividendYield-0.5*DB5^2)*TimeToExpiration)/(DB5*TimeToExpiration^0.5), 0, 1, TRUE) ) -> 45.075021 | DE5: =(DA5+DB5)/2 -> 0.60529832 | DF5: =DF$2*(Underlying*EXP(-DividendYield*TimeToExpiration)*_xlfn.NORM.DIST(DF$2*(LN(Underlying/$H5)+(RiskFreeRate-DividendYield+0.5*DE5^2)*TimeToExpiration)/(DE5*TimeToExpiration^0.5), 0, 1, TRUE) - $H5*EXP(-RiskFreeRate*TimeToExpiration)*_xlfn.NORM.DIST(DF$2*(LN(Underlying/$H5)+(RiskFreeRate-DividendYield-0.5*DE5^2)*TimeToExpiration)/(DE5*TimeToExpiration^0.5), 0, 1, TRUE) ) -> 45.074915
A6: ='Option Mkt Data'!A6 -> 297.5 | B6: =DE6 -> 0.0010228806 | C6: =DF6 -> 42.009401 | D6: =ABS(C6-G6) -> 0.20939776 | E6: =D6/G6 -> 0.0050095153 | F6: =D6/'Option Mkt Data'!L6 -> 0.065436549 | G6: ='Option Mkt Data'!J6 -> 41.800003 | H6: ='Option Mkt Data'!A6 -> 297.5 | I6: =MinSolverVola -> 0.001 | J6: =MaxSolverVola -> 3 | K6: =K$2*(Underlying*EXP(-DividendYield*TimeToExpiration)*_xlfn.NORM.DIST(K$2*(LN(Underlying/$H6)+(RiskFreeRate-DividendYield+0.5*I6^2)*TimeToExpiration)/(I6*TimeToExpiration^0.5), 0, 1, TRUE) - $H6*EXP(-RiskFreeRate*TimeToExpiration)*_xlfn.NORM.DIST(K$2*(LN(Underlying/$H6)+(RiskFreeRate-DividendYield-0.5*I6^2)*TimeToExpiration)/(I6*TimeToExpiration^0.5), 0, 1, TRUE) ) -> 42.009401 | L6: =L$2*(Underlying*EXP(-DividendYield*TimeToExpiration)*_xlfn.NORM.DIST(L$2*(LN(Underlying/$H6)+(RiskFreeRate-DividendYield+0.5*J6^2)*TimeToExpiration)/(J6*TimeToExpiration^0.5), 0, 1, TRUE) - $H6*EXP(-RiskFreeRate*TimeToExpiration)*_xlfn.NORM.DIST(L$2*(LN(Underlying/$H6)+(RiskFreeRate-DividendYield-0.5*J6^2)*TimeToExpiration)/(J6*TimeToExpiration^0.5), 0, 1, TRUE) ) -> 76.997749 | M6: =(I6+J6)/2 -> 1.5005 | N6: =N$2*(Underlying*EXP(-DividendYield*TimeToExpiration)*_xlfn.NORM.DIST(N$2*(LN(Underlying/$H6)+(RiskFreeRate-DividendYield+0.5*M6^2)*TimeToExpiration)/(M6*TimeToExpiration^0.5), 0, 1, TRUE) - $H6*EXP(-RiskFreeRate*TimeToExpiration)*_xlfn.NORM.DIST(N$2*(LN(Underlying/$H6)+(RiskFreeRate-DividendYield-0.5*M6^2)*TimeToExpiration)/(M6*TimeToExpiration^0.5), 0, 1, TRUE) ) -> 52.922332 | O6: =IF(N6>$G6, I6, M6) -> 0.001 | P6: =IF(N6>$G6, M6, J6) -> 1.5005 | Q6: =Q$2*(Underlying*EXP(-DividendYield*TimeToExpiration)*_xlfn.NORM.DIST(Q$2*(LN(Underlying/$H6)+(RiskFreeRate-DividendYield+0.5*O6^2)*TimeToExpiration)/(O6*TimeToExpiration^0.5), 0, 1, TRUE) - $H6*EXP(-RiskFreeRate*TimeToExpiration)*_xlfn.NORM.DIST(Q$2*(LN(Underlying/$H6)+(RiskFreeRate-DividendYield-0.5*O6^2)*TimeToExpiration)/(O6*TimeToExpiration^0.5), 0, 1, TRUE)) -> 42.009401 | R6: =R$2*(Underlying*EXP(-DividendYield*TimeToExpiration)*_xlfn.NORM.DIST(R$2*(LN(Underlying/$H6)+(RiskFreeRate-DividendYield+0.5*P6^2)*TimeToExpiration)/(P6*TimeToExpiration^0.5), 0, 1, TRUE) - $H6*EXP(-RiskFreeRate*TimeToExpiration)*_xlfn.NORM.DIST(R$2*(LN(Underlying/$H6)+(RiskFreeRate-DividendYield-0.5*P6^2)*TimeToExpiration)/(P6*TimeToExpiration^0.5), 0, 1, TRUE) ) -> 52.922332 | S6: =(O6+P6)/2 -> 0.75075 | T6: =T$2*(Underlying*EXP(-DividendYield*TimeToExpiration)*_xlfn.NORM.DIST(T$2*(LN(Underlying/$H6)+(RiskFreeRate-DividendYield+0.5*S6^2)*TimeToExpiration)/(S6*TimeToExpiration^0.5), 0, 1, TRUE) - $H6*EXP(-RiskFreeRate*TimeToExpiration)*_xlfn.NORM.DIST(T$2*(LN(Underlying/$H6)+(RiskFreeRate-DividendYield-0.5*S6^2)*TimeToExpiration)/(S6*TimeToExpiration^0.5), 0, 1, TRUE) ) -> 43.730499 | U6: =IF(T6>$G6, O6, S6) -> 0.001 | V6: =IF(T6>$G6, S6, P6) -> 0.75075 | W6: =W$2*(Underlying*EXP(-DividendYield*TimeToExpiration)*_xlfn.NORM.DIST(W$2*(LN(Underlying/$H6)+(RiskFreeRate-DividendYield+0.5*U6^2)*TimeToExpiration)/(U6*TimeToExpiration^0.5), 0, 1, TRUE) - $H6*EXP(-RiskFreeRate*TimeToExpiration)*_xlfn.NORM.DIST(W$2*(LN(Underlying/$H6)+(RiskFreeRate-DividendYield-0.5*U6^2)*TimeToExpiration)/(U6*TimeToExpiration^0.5), 0, 1, TRUE) ) -> 42.009401 | X6: =X$2*(Underlying*EXP(-DividendYield*TimeToExpiration)*_xlfn.NORM.DIST(X$2*(LN(Underlying/$H6)+(RiskFreeRate-DividendYield+0.5*V6^2)*TimeToExpiration)/(V6*TimeToExpiration^0.5), 0, 1, TRUE) - $H6*EXP(-RiskFreeRate*TimeToExpiration)*_xlfn.NORM.DIST(X$2*(LN(Underlying/$H6)+(RiskFreeRate-DividendYield-0.5*V6^2)*TimeToExpiration)/(V6*TimeToExpiration^0.5), 0, 1, TRUE) ) -> 43.730499 | Y6: =(U6+V6)/2 -> 0.375875 | Z6: =Z$2*(Underlying*EXP(-DividendYield*TimeToExpiration)*_xlfn.NORM.DIST(Z$2*(LN(Underlying/$H6)+(RiskFreeRate-DividendYield+0.5*Y6^2)*TimeToExpiration)/(Y6*TimeToExpiration^0.5), 0, 1, TRUE) - $H6*EXP(-RiskFreeRate*TimeToExpiration)*_xlfn.NORM.DIST(Z$2*(LN(Underlying/$H6)+(RiskFreeRate-DividendYield-0.5*Y6^2)*TimeToExpiration)/(Y6*TimeToExpiration^0.5), 0, 1, TRUE) ) -> 42.044605 | AA6: =IF(Z6>$G6, U6, Y6) -> 0.001 | AB6: =IF(Z6>$G6, Y6, V6) -> 0.375875 | AC6: =AC$2*(Underlying*EXP(-DividendYield*TimeToExpiration)*_xlfn.NORM.DIST(AC$2*(LN(Underlying/$H6)+(RiskFreeRate-DividendYield+0.5*AA6^2)*TimeToExpiration)/(AA6*TimeToExpiration^0.5), 0, 1, TRUE) - $H6*EXP(-RiskFreeRate*TimeToExpiration)*_xlfn.NORM.DIST(AC$2*(LN(Underlying/$H6)+(RiskFreeRate-DividendYield-0.5*AA6^2)*TimeToExpiration)/(AA6*TimeToExpiration^0.5), 0, 1, TRUE) ) -> 42.009401 | AD6: =AD$2*(Underlying*EXP(-DividendYield*TimeToExpiration)*_xlfn.NORM.DIST(AD$2*(LN(Underlying/$H6)+(RiskFreeRate-DividendYield+0.5*AB6^2)*TimeToExpiration)/(AB6*TimeToExpiration^0.5), 0, 1, TRUE) - $H6*EXP(-RiskFreeRate*TimeToExpiration)*_xlfn.NORM.DIST(AD$2*(LN(Underlying/$H6)+(RiskFreeRate-DividendYield-0.5*AB6^2)*TimeToExpiration)/(AB6*TimeToExpiration^0.5), 0, 1, TRUE) ) -> 42.044605 | AE6: =(AA6+AB6)/2 -> 0.1884375 | AF6: =AF$2*(Underlying*EXP(-DividendYield*TimeToExpiration)*_xlfn.NORM.DIST(AF$2*(LN(Underlying/$H6)+(RiskFreeRate-DividendYield+0.5*AE6^2)*TimeToExpiration)/(AE6*TimeToExpiration^0.5), 0, 1, TRUE) - $H6*EXP(-RiskFreeRate*TimeToExpiration)*_xlfn.NORM.DIST(AF$2*(LN(Underlying/$H6)+(RiskFreeRate-DividendYield-0.5*AE6^2)*TimeToExpiration)/(AE6*TimeToExpiration^0.5), 0, 1, TRUE) ) -> 42.009401 | AG6: =IF(AF6>$G6, AA6, AE6) -> 0.001 | AH6: =IF(AF6>$G6, AE6, AB6) -> 0.1884375 | AI6: =AI$2*(Underlying*EXP(-DividendYield*TimeToExpiration)*_xlfn.NORM.DIST(AI$2*(LN(Underlying/$H6)+(RiskFreeRate-DividendYield+0.5*AG6^2)*TimeToExpiration)/(AG6*TimeToExpiration^0.5), 0, 1, TRUE) - $H6*EXP(-RiskFreeRate*TimeToExpiration)*_xlfn.NORM.DIST(AI$2*(LN(Underlying/$H6)+(RiskFreeRate-DividendYield-0.5*AG6^2)*TimeToExpiration)/(AG6*TimeToExpiration^0.5), 0, 1, TRUE) ) -> 42.009401 | AJ6: =AJ$2*(Underlying*EXP(-DividendYield*TimeToExpiration)*_xlfn.NORM.DIST(AJ$2*(LN(Underlying/$H6)+(RiskFreeRate-DividendYield+0.5*AH6^2)*TimeToExpiration)/(AH6*TimeToExpiration^0.5), 0, 1, TRUE) - $H6*EXP(-RiskFreeRate*TimeToExpiration)*_xlfn.NORM.DIST(AJ$2*(LN(Underlying/$H6)+(RiskFreeRate-DividendYield-0.5*AH6^2)*TimeToExpiration)/(AH6*TimeToExpiration^0.5), 0, 1, TRUE) ) -> 42.009401 | AK6: =(AG6+AH6)/2 -> 0.09471875 | AL6: =AL$2*(Underlying*EXP(-DividendYield*TimeToExpiration)*_xlfn.NORM.DIST(AL$2*(LN(Underlying/$H6)+(RiskFreeRate-DividendYield+0.5*AK6^2)*TimeToExpiration)/(AK6*TimeToExpiration^0.5), 0, 1, TRUE) - $H6*EXP(-RiskFreeRate*TimeToExpiration)*_xlfn.NORM.DIST(AL$2*(LN(Underlying/$H6)+(RiskFreeRate-DividendYield-0.5*AK6^2)*TimeToExpiration)/(AK6*TimeToExpiration^0.5), 0, 1, TRUE) ) -> 42.009401 | AM6: =IF(AL6>$G6, AG6, AK6) -> 0.001 | AN6: =IF(AL6>$G6, AK6, AH6) -> 0.09471875 | AO6: =AO$2*(Underlying*EXP(-DividendYield*TimeToExpiration)*_xlfn.NORM.DIST(AO$2*(LN(Underlying/$H6)+(RiskFreeRate-DividendYield+0.5*AM6^2)*TimeToExpiration)/(AM6*TimeToExpiration^0.5), 0, 1, TRUE) - $H6*EXP(-RiskFreeRate*TimeToExpiration)*_xlfn.NORM.DIST(AO$2*(LN(Underlying/$H6)+(RiskFreeRate-DividendYield-0.5*AM6^2)*TimeToExpiration)/(AM6*TimeToExpiration^0.5), 0, 1, TRUE) ) -> 42.009401 | AP6: =AP$2*(Underlying*EXP(-DividendYield*TimeToExpiration)*_xlfn.NORM.DIST(AP$2*(LN(Underlying/$H6)+(RiskFreeRate-DividendYield+0.5*AN6^2)*TimeToExpiration)/(AN6*TimeToExpiration^0.5), 0, 1, TRUE) - $H6*EXP(-RiskFreeRate*TimeToExpiration)*_xlfn.NORM.DIST(AP$2*(LN(Underlying/$H6)+(RiskFreeRate-DividendYield-0.5*AN6^2)*TimeToExpiration)/(AN6*TimeToExpiration^0.5), 0, 1, TRUE) ) -> 42.009401 | AQ6: =(AM6+AN6)/2 -> 0.047859375 | AR6: =AR$2*(Underlying*EXP(-DividendYield*TimeToExpiration)*_xlfn.NORM.DIST(AR$2*(LN(Underlying/$H6)+(RiskFreeRate-DividendYield+0.5*AQ6^2)*TimeToExpiration)/(AQ6*TimeToExpiration^0.5), 0, 1, TRUE) - $H6*EXP(-RiskFreeRate*TimeToExpiration)*_xlfn.NORM.DIST(AR$2*(LN(Underlying/$H6)+(RiskFreeRate-DividendYield-0.5*AQ6^2)*TimeToExpiration)/(AQ6*TimeToExpiration^0.5), 0, 1, TRUE) ) -> 42.009401 | AS6: =IF(AR6>$G6, AM6, AQ6) -> 0.001 | AT6: =IF(AR6>$G6, AQ6, AN6) -> 0.047859375 | AU6: =AU$2*(Underlying*EXP(-DividendYield*TimeToExpiration)*_xlfn.NORM.DIST(AU$2*(LN(Underlying/$H6)+(RiskFreeRate-DividendYield+0.5*AS6^2)*TimeToExpiration)/(AS6*TimeToExpiration^0.5), 0, 1, TRUE) - $H6*EXP(-RiskFreeRate*TimeToExpiration)*_xlfn.NORM.DIST(AU$2*(LN(Underlying/$H6)+(RiskFreeRate-DividendYield-0.5*AS6^2)*TimeToExpiration)/(AS6*TimeToExpiration^0.5), 0, 1, TRUE) ) -> 42.009401 | AV6: =AV$2*(Underlying*EXP(-DividendYield*TimeToExpiration)*_xlfn.NORM.DIST(AV$2*(LN(Underlying/$H6)+(RiskFreeRate-DividendYield+0.5*AT6^2)*TimeToExpiration)/(AT6*TimeToExpiration^0.5), 0, 1, TRUE) - $H6*EXP(-RiskFreeRate*TimeToExpiration)*_xlfn.NORM.DIST(AV$2*(LN(Underlying/$H6)+(RiskFreeRate-DividendYield-0.5*AT6^2)*TimeToExpiration)/(AT6*TimeToExpiration^0.5), 0, 1, TRUE) ) -> 42.009401 | AW6: =(AS6+AT6)/2 -> 0.024429687 | AX6: =AX$2*(Underlying*EXP(-DividendYield*TimeToExpiration)*_xlfn.NORM.DIST(AX$2*(LN(Underlying/$H6)+(RiskFreeRate-DividendYield+0.5*AW6^2)*TimeToExpiration)/(AW6*TimeToExpiration^0.5), 0, 1, TRUE) - $H6*EXP(-RiskFreeRate*TimeToExpiration)*_xlfn.NORM.DIST(AX$2*(LN(Underlying/$H6)+(RiskFreeRate-DividendYield-0.5*AW6^2)*TimeToExpiration)/(AW6*TimeToExpiration^0.5), 0, 1, TRUE) ) -> 42.009401 | AY6: =IF(AX6>$G6, AS6, AW6) -> 0.001 | AZ6: =IF(AX6>$G6, AW6, AT6) -> 0.024429687 | BA6: =BA$2*(Underlying*EXP(-DividendYield*TimeToExpiration)*_xlfn.NORM.DIST(BA$2*(LN(Underlying/$H6)+(RiskFreeRate-DividendYield+0.5*AY6^2)*TimeToExpiration)/(AY6*TimeToExpiration^0.5), 0, 1, TRUE) - $H6*EXP(-RiskFreeRate*TimeToExpiration)*_xlfn.NORM.DIST(BA$2*(LN(Underlying/$H6)+(RiskFreeRate-DividendYield-0.5*AY6^2)*TimeToExpiration)/(AY6*TimeToExpiration^0.5), 0, 1, TRUE) ) -> 42.009401 | BB6: =BB$2*(Underlying*EXP(-DividendYield*TimeToExpiration)*_xlfn.NORM.DIST(BB$2*(LN(Underlying/$H6)+(RiskFreeRate-DividendYield+0.5*AZ6^2)*TimeToExpiration)/(AZ6*TimeToExpiration^0.5), 0, 1, TRUE) - $H6*EXP(-RiskFreeRate*TimeToExpiration)*_xlfn.NORM.DIST(BB$2*(LN(Underlying/$H6)+(RiskFreeRate-DividendYield-0.5*AZ6^2)*TimeToExpiration)/(AZ6*TimeToExpiration^0.5), 0, 1, TRUE) ) -> 42.009401 | BC6: =(AY6+AZ6)/2 -> 0.012714844 | BD6: =BD$2*(Underlying*EXP(-DividendYield*TimeToExpiration)*_xlfn.NORM.DIST(BD$2*(LN(Underlying/$H6)+(RiskFreeRate-DividendYield+0.5*BC6^2)*TimeToExpiration)/(BC6*TimeToExpiration^0.5), 0, 1, TRUE) - $H6*EXP(-RiskFreeRate*TimeToExpiration)*_xlfn.NORM.DIST(BD$2*(LN(Underlying/$H6)+(RiskFreeRate-DividendYield-0.5*BC6^2)*TimeToExpiration)/(BC6*TimeToExpiration^0.5), 0, 1, TRUE) ) -> 42.009401 | BE6: =IF(BD6>$G6, AY6, BC6) -> 0.001 | BF6: =IF(BD6>$G6, BC6, AZ6) -> 0.012714844 | BG6: =BG$2*(Underlying*EXP(-DividendYield*TimeToExpiration)*_xlfn.NORM.DIST(BG$2*(LN(Underlying/$H6)+(RiskFreeRate-DividendYield+0.5*BE6^2)*TimeToExpiration)/(BE6*TimeToExpiration^0.5), 0, 1, TRUE) - $H6*EXP(-RiskFreeRate*TimeToExpiration)*_xlfn.NORM.DIST(BG$2*(LN(Underlying/$H6)+(RiskFreeRate-DividendYield-0.5*BE6^2)*TimeToExpiration)/(BE6*TimeToExpiration^0.5), 0, 1, TRUE) ) -> 42.009401 | BH6: =BH$2*(Underlying*EXP(-DividendYield*TimeToExpiration)*_xlfn.NORM.DIST(BH$2*(LN(Underlying/$H6)+(RiskFreeRate-DividendYield+0.5*BF6^2)*TimeToExpiration)/(BF6*TimeToExpiration^0.5), 0, 1, TRUE) - $H6*EXP(-RiskFreeRate*TimeToExpiration)*_xlfn.NORM.DIST(BH$2*(LN(Underlying/$H6)+(RiskFreeRate-DividendYield-0.5*BF6^2)*TimeToExpiration)/(BF6*TimeToExpiration^0.5), 0, 1, TRUE) ) -> 42.009401 | BI6: =(BE6+BF6)/2 -> 0.0068574219 | BJ6: =BJ$2*(Underlying*EXP(-DividendYield*TimeToExpiration)*_xlfn.NORM.DIST(BJ$2*(LN(Underlying/$H6)+(RiskFreeRate-DividendYield+0.5*BI6^2)*TimeToExpiration)/(BI6*TimeToExpiration^0.5), 0, 1, TRUE) - $H6*EXP(-RiskFreeRate*TimeToExpiration)*_xlfn.NORM.DIST(BJ$2*(LN(Underlying/$H6)+(RiskFreeRate-DividendYield-0.5*BI6^2)*TimeToExpiration)/(BI6*TimeToExpiration^0.5), 0, 1, TRUE) ) -> 42.009401 | BK6: =IF(BJ6>$G6, BE6, BI6) -> 0.001 | BL6: =IF(BJ6>$G6, BI6, BF6) -> 0.0068574219 | BM6: =BM$2*(Underlying*EXP(-DividendYield*TimeToExpiration)*_xlfn.NORM.DIST(BM$2*(LN(Underlying/$H6)+(RiskFreeRate-DividendYield+0.5*BK6^2)*TimeToExpiration)/(BK6*TimeToExpiration^0.5), 0, 1, TRUE) - $H6*EXP(-RiskFreeRate*TimeToExpiration)*_xlfn.NORM.DIST(BM$2*(LN(Underlying/$H6)+(RiskFreeRate-DividendYield-0.5*BK6^2)*TimeToExpiration)/(BK6*TimeToExpiration^0.5), 0, 1, TRUE) ) -> 42.009401 | BN6: =BN$2*(Underlying*EXP(-DividendYield*TimeToExpiration)*_xlfn.NORM.DIST(BN$2*(LN(Underlying/$H6)+(RiskFreeRate-DividendYield+0.5*BL6^2)*TimeToExpiration)/(BL6*TimeToExpiration^0.5), 0, 1, TRUE) - $H6*EXP(-RiskFreeRate*TimeToExpiration)*_xlfn.NORM.DIST(BN$2*(LN(Underlying/$H6)+(RiskFreeRate-DividendYield-0.5*BL6^2)*TimeToExpiration)/(BL6*TimeToExpiration^0.5), 0, 1, TRUE) ) -> 42.009401 | BO6: =(BK6+BL6)/2 -> 0.0039287109 | BP6: =BP$2*(Underlying*EXP(-DividendYield*TimeToExpiration)*_xlfn.NORM.DIST(BP$2*(LN(Underlying/$H6)+(RiskFreeRate-DividendYield+0.5*BO6^2)*TimeToExpiration)/(BO6*TimeToExpiration^0.5), 0, 1, TRUE) - $H6*EXP(-RiskFreeRate*TimeToExpiration)*_xlfn.NORM.DIST(BP$2*(LN(Underlying/$H6)+(RiskFreeRate-DividendYield-0.5*BO6^2)*TimeToExpiration)/(BO6*TimeToExpiration^0.5), 0, 1, TRUE) ) -> 42.009401 | BQ6: =IF(BP6>$G6, BK6, BO6) -> 0.001 | BR6: =IF(BP6>$G6, BO6, BL6) -> 0.0039287109 | BS6: =BS$2*(Underlying*EXP(-DividendYield*TimeToExpiration)*_xlfn.NORM.DIST(BS$2*(LN(Underlying/$H6)+(RiskFreeRate-DividendYield+0.5*BQ6^2)*TimeToExpiration)/(BQ6*TimeToExpiration^0.5), 0, 1, TRUE) - $H6*EXP(-RiskFreeRate*TimeToExpiration)*_xlfn.NORM.DIST(BS$2*(LN(Underlying/$H6)+(RiskFreeRate-DividendYield-0.5*BQ6^2)*TimeToExpiration)/(BQ6*TimeToExpiration^0.5), 0, 1, TRUE) ) -> 42.009401 | BT6: =BT$2*(Underlying*EXP(-DividendYield*TimeToExpiration)*_xlfn.NORM.DIST(BT$2*(LN(Underlying/$H6)+(RiskFreeRate-DividendYield+0.5*BR6^2)*TimeToExpiration)/(BR6*TimeToExpiration^0.5), 0, 1, TRUE) - $H6*EXP(-RiskFreeRate*TimeToExpiration)*_xlfn.NORM.DIST(BT$2*(LN(Underlying/$H6)+(RiskFreeRate-DividendYield-0.5*BR6^2)*TimeToExpiration)/(BR6*TimeToExpiration^0.5), 0, 1, TRUE) ) -> 42.009401 | BU6: =(BQ6+BR6)/2 -> 0.0024643555 | BV6: =BV$2*(Underlying*EXP(-DividendYield*TimeToExpiration)*_xlfn.NORM.DIST(BV$2*(LN(Underlying/$H6)+(RiskFreeRate-DividendYield+0.5*BU6^2)*TimeToExpiration)/(BU6*TimeToExpiration^0.5), 0, 1, TRUE) - $H6*EXP(-RiskFreeRate*TimeToExpiration)*_xlfn.NORM.DIST(BV$2*(LN(Underlying/$H6)+(RiskFreeRate-DividendYield-0.5*BU6^2)*TimeToExpiration)/(BU6*TimeToExpiration^0.5), 0, 1, TRUE) ) -> 42.009401 | BW6: =IF(BV6>$G6, BQ6, BU6) -> 0.001 | BX6: =IF(BV6>$G6, BU6, BR6) -> 0.0024643555 | BY6: =BY$2*(Underlying*EXP(-DividendYield*TimeToExpiration)*_xlfn.NORM.DIST(BY$2*(LN(Underlying/$H6)+(RiskFreeRate-DividendYield+0.5*BW6^2)*TimeToExpiration)/(BW6*TimeToExpiration^0.5), 0, 1, TRUE) - $H6*EXP(-RiskFreeRate*TimeToExpiration)*_xlfn.NORM.DIST(BY$2*(LN(Underlying/$H6)+(RiskFreeRate-DividendYield-0.5*BW6^2)*TimeToExpiration)/(BW6*TimeToExpiration^0.5), 0, 1, TRUE) ) -> 42.009401 | BZ6: =BZ$2*(Underlying*EXP(-DividendYield*TimeToExpiration)*_xlfn.NORM.DIST(BZ$2*(LN(Underlying/$H6)+(RiskFreeRate-DividendYield+0.5*BX6^2)*TimeToExpiration)/(BX6*TimeToExpiration^0.5), 0, 1, TRUE) - $H6*EXP(-RiskFreeRate*TimeToExpiration)*_xlfn.NORM.DIST(BZ$2*(LN(Underlying/$H6)+(RiskFreeRate-DividendYield-0.5*BX6^2)*TimeToExpiration)/(BX6*TimeToExpiration^0.5), 0, 1, TRUE) ) -> 42.009401 | CA6: =(BW6+BX6)/2 -> 0.0017321777 | CB6: =CB$2*(Underlying*EXP(-DividendYield*TimeToExpiration)*_xlfn.NORM.DIST(CB$2*(LN(Underlying/$H6)+(RiskFreeRate-DividendYield+0.5*CA6^2)*TimeToExpiration)/(CA6*TimeToExpiration^0.5), 0, 1, TRUE) - $H6*EXP(-RiskFreeRate*TimeToExpiration)*_xlfn.NORM.DIST(CB$2*(LN(Underlying/$H6)+(RiskFreeRate-DividendYield-0.5*CA6^2)*TimeToExpiration)/(CA6*TimeToExpiration^0.5), 0, 1, TRUE) ) -> 42.009401 | CC6: =IF(CB6>$G6, BW6, CA6) -> 0.001 | CD6: =IF(CB6>$G6, CA6, BX6) -> 0.0017321777 | CE6: =CE$2*(Underlying*EXP(-DividendYield*TimeToExpiration)*_xlfn.NORM.DIST(CE$2*(LN(Underlying/$H6)+(RiskFreeRate-DividendYield+0.5*CC6^2)*TimeToExpiration)/(CC6*TimeToExpiration^0.5), 0, 1, TRUE) - $H6*EXP(-RiskFreeRate*TimeToExpiration)*_xlfn.NORM.DIST(CE$2*(LN(Underlying/$H6)+(RiskFreeRate-DividendYield-0.5*CC6^2)*TimeToExpiration)/(CC6*TimeToExpiration^0.5), 0, 1, TRUE) ) -> 42.009401 | CF6: =CF$2*(Underlying*EXP(-DividendYield*TimeToExpiration)*_xlfn.NORM.DIST(CF$2*(LN(Underlying/$H6)+(RiskFreeRate-DividendYield+0.5*CD6^2)*TimeToExpiration)/(CD6*TimeToExpiration^0.5), 0, 1, TRUE) - $H6*EXP(-RiskFreeRate*TimeToExpiration)*_xlfn.NORM.DIST(CF$2*(LN(Underlying/$H6)+(RiskFreeRate-DividendYield-0.5*CD6^2)*TimeToExpiration)/(CD6*TimeToExpiration^0.5), 0, 1, TRUE) ) -> 42.009401 | CG6: =(CC6+CD6)/2 -> 0.0013660889 | CH6: =CH$2*(Underlying*EXP(-DividendYield*TimeToExpiration)*_xlfn.NORM.DIST(CH$2*(LN(Underlying/$H6)+(RiskFreeRate-DividendYield+0.5*CG6^2)*TimeToExpiration)/(CG6*TimeToExpiration^0.5), 0, 1, TRUE) - $H6*EXP(-RiskFreeRate*TimeToExpiration)*_xlfn.NORM.DIST(CH$2*(LN(Underlying/$H6)+(RiskFreeRate-DividendYield-0.5*CG6^2)*TimeToExpiration)/(CG6*TimeToExpiration^0.5), 0, 1, TRUE) ) -> 42.009401 | CI6: =IF(CH6>$G6, CC6, CG6) -> 0.001 | CJ6: =IF(CH6>$G6, CG6, CD6) -> 0.0013660889 | CK6: =CK$2*(Underlying*EXP(-DividendYield*TimeToExpiration)*_xlfn.NORM.DIST(CK$2*(LN(Underlying/$H6)+(RiskFreeRate-DividendYield+0.5*CI6^2)*TimeToExpiration)/(CI6*TimeToExpiration^0.5), 0, 1, TRUE) - $H6*EXP(-RiskFreeRate*TimeToExpiration)*_xlfn.NORM.DIST(CK$2*(LN(Underlying/$H6)+(RiskFreeRate-DividendYield-0.5*CI6^2)*TimeToExpiration)/(CI6*TimeToExpiration^0.5), 0, 1, TRUE) ) -> 42.009401 | CL6: =CL$2*(Underlying*EXP(-DividendYield*TimeToExpiration)*_xlfn.NORM.DIST(CL$2*(LN(Underlying/$H6)+(RiskFreeRate-DividendYield+0.5*CJ6^2)*TimeToExpiration)/(CJ6*TimeToExpiration^0.5), 0, 1, TRUE) - $H6*EXP(-RiskFreeRate*TimeToExpiration)*_xlfn.NORM.DIST(CL$2*(LN(Underlying/$H6)+(RiskFreeRate-DividendYield-0.5*CJ6^2)*TimeToExpiration)/(CJ6*TimeToExpiration^0.5), 0, 1, TRUE) ) -> 42.009401 | CM6: =(CI6+CJ6)/2 -> 0.0011830444 | CN6: =CN$2*(Underlying*EXP(-DividendYield*TimeToExpiration)*_xlfn.NORM.DIST(CN$2*(LN(Underlying/$H6)+(RiskFreeRate-DividendYield+0.5*CM6^2)*TimeToExpiration)/(CM6*TimeToExpiration^0.5), 0, 1, TRUE) - $H6*EXP(-RiskFreeRate*TimeToExpiration)*_xlfn.NORM.DIST(CN$2*(LN(Underlying/$H6)+(RiskFreeRate-DividendYield-0.5*CM6^2)*TimeToExpiration)/(CM6*TimeToExpiration^0.5), 0, 1, TRUE) ) -> 42.009401 | CO6: =IF(CN6>$G6, CI6, CM6) -> 0.001 | CP6: =IF(CN6>$G6, CM6, CJ6) -> 0.0011830444 | CQ6: =CQ$2*(Underlying*EXP(-DividendYield*TimeToExpiration)*_xlfn.NORM.DIST(CQ$2*(LN(Underlying/$H6)+(RiskFreeRate-DividendYield+0.5*CO6^2)*TimeToExpiration)/(CO6*TimeToExpiration^0.5), 0, 1, TRUE) - $H6*EXP(-RiskFreeRate*TimeToExpiration)*_xlfn.NORM.DIST(CQ$2*(LN(Underlying/$H6)+(RiskFreeRate-DividendYield-0.5*CO6^2)*TimeToExpiration)/(CO6*TimeToExpiration^0.5), 0, 1, TRUE) ) -> 42.009401 | CR6: =CR$2*(Underlying*EXP(-DividendYield*TimeToExpiration)*_xlfn.NORM.DIST(CR$2*(LN(Underlying/$H6)+(RiskFreeRate-DividendYield+0.5*CP6^2)*TimeToExpiration)/(CP6*TimeToExpiration^0.5), 0, 1, TRUE) - $H6*EXP(-RiskFreeRate*TimeToExpiration)*_xlfn.NORM.DIST(CR$2*(LN(Underlying/$H6)+(RiskFreeRate-DividendYield-0.5*CP6^2)*TimeToExpiration)/(CP6*TimeToExpiration^0.5), 0, 1, TRUE) ) -> 42.009401 | CS6: =(CO6+CP6)/2 -> 0.0010915222 | CT6: =CT$2*(Underlying*EXP(-DividendYield*TimeToExpiration)*_xlfn.NORM.DIST(CT$2*(LN(Underlying/$H6)+(RiskFreeRate-DividendYield+0.5*CS6^2)*TimeToExpiration)/(CS6*TimeToExpiration^0.5), 0, 1, TRUE) - $H6*EXP(-RiskFreeRate*TimeToExpiration)*_xlfn.NORM.DIST(CT$2*(LN(Underlying/$H6)+(RiskFreeRate-DividendYield-0.5*CS6^2)*TimeToExpiration)/(CS6*TimeToExpiration^0.5), 0, 1, TRUE) ) -> 42.009401 | CU6: =IF(CT6>$G6, CO6, CS6) -> 0.001 | CV6: =IF(CT6>$G6, CS6, CP6) -> 0.0010915222 | CW6: =CW$2*(Underlying*EXP(-DividendYield*TimeToExpiration)*_xlfn.NORM.DIST(CW$2*(LN(Underlying/$H6)+(RiskFreeRate-DividendYield+0.5*CU6^2)*TimeToExpiration)/(CU6*TimeToExpiration^0.5), 0, 1, TRUE) - $H6*EXP(-RiskFreeRate*TimeToExpiration)*_xlfn.NORM.DIST(CW$2*(LN(Underlying/$H6)+(RiskFreeRate-DividendYield-0.5*CU6^2)*TimeToExpiration)/(CU6*TimeToExpiration^0.5), 0, 1, TRUE) ) -> 42.009401 | CX6: =CX$2*(Underlying*EXP(-DividendYield*TimeToExpiration)*_xlfn.NORM.DIST(CX$2*(LN(Underlying/$H6)+(RiskFreeRate-DividendYield+0.5*CV6^2)*TimeToExpiration)/(CV6*TimeToExpiration^0.5), 0, 1, TRUE) - $H6*EXP(-RiskFreeRate*TimeToExpiration)*_xlfn.NORM.DIST(CX$2*(LN(Underlying/$H6)+(RiskFreeRate-DividendYield-0.5*CV6^2)*TimeToExpiration)/(CV6*TimeToExpiration^0.5), 0, 1, TRUE) ) -> 42.009401 | CY6: =(CU6+CV6)/2 -> 0.0010457611 | CZ6: =CZ$2*(Underlying*EXP(-DividendYield*TimeToExpiration)*_xlfn.NORM.DIST(CZ$2*(LN(Underlying/$H6)+(RiskFreeRate-DividendYield+0.5*CY6^2)*TimeToExpiration)/(CY6*TimeToExpiration^0.5), 0, 1, TRUE) - $H6*EXP(-RiskFreeRate*TimeToExpiration)*_xlfn.NORM.DIST(CZ$2*(LN(Underlying/$H6)+(RiskFreeRate-DividendYield-0.5*CY6^2)*TimeToExpiration)/(CY6*TimeToExpiration^0.5), 0, 1, TRUE) ) -> 42.009401 | DA6: =IF(CZ6>$G6, CU6, CY6) -> 0.001 | DB6: =IF(CZ6>$G6, CY6, CV6) -> 0.0010457611 | DC6: =DC$2*(Underlying*EXP(-DividendYield*TimeToExpiration)*_xlfn.NORM.DIST(DC$2*(LN(Underlying/$H6)+(RiskFreeRate-DividendYield+0.5*DA6^2)*TimeToExpiration)/(DA6*TimeToExpiration^0.5), 0, 1, TRUE) - $H6*EXP(-RiskFreeRate*TimeToExpiration)*_xlfn.NORM.DIST(DC$2*(LN(Underlying/$H6)+(RiskFreeRate-DividendYield-0.5*DA6^2)*TimeToExpiration)/(DA6*TimeToExpiration^0.5), 0, 1, TRUE) ) -> 42.009401 | DD6: =DD$2*(Underlying*EXP(-DividendYield*TimeToExpiration)*_xlfn.NORM.DIST(DD$2*(LN(Underlying/$H6)+(RiskFreeRate-DividendYield+0.5*DB6^2)*TimeToExpiration)/(DB6*TimeToExpiration^0.5), 0, 1, TRUE) - $H6*EXP(-RiskFreeRate*TimeToExpiration)*_xlfn.NORM.DIST(DD$2*(LN(Underlying/$H6)+(RiskFreeRate-DividendYield-0.5*DB6^2)*TimeToExpiration)/(DB6*TimeToExpiration^0.5), 0, 1, TRUE) ) -> 42.009401 | DE6: =(DA6+DB6)/2 -> 0.0010228806 | DF6: =DF$2*(Underlying*EXP(-DividendYield*TimeToExpiration)*_xlfn.NORM.DIST(DF$2*(LN(Underlying/$H6)+(RiskFreeRate-DividendYield+0.5*DE6^2)*TimeToExpiration)/(DE6*TimeToExpiration^0.5), 0, 1, TRUE) - $H6*EXP(-RiskFreeRate*TimeToExpiration)*_xlfn.NORM.DIST(DF$2*(LN(Underlying/$H6)+(RiskFreeRate-DividendYield-0.5*DE6^2)*TimeToExpiration)/(DE6*TimeToExpiration^0.5), 0, 1, TRUE) ) -> 42.009401
